Workbook

Sheet ESTRUCTURA

Sheet HOGARES-BASELINE
A1: # | B1: start_p10 | C1: Nombres | D1: Municipio | E1: ETAPA | F1: identificador de etapa | G1: identificador de ciudad | H1: identificador de hogar | I1: house_id
A2: 1 | B2: 1000193972 | C2: =VLOOKUP(B2,[1]BD_FINAL!$A:$H,2,FALSE) -> Juan Pablo | D2: =VLOOKUP(B2,[1]BD_FINAL!$A:$H,3,FALSE) -> Medellin | E2: =VLOOKUP(B2,[1]BD_FINAL!$A:$H,8,FALSE) -> Control | F2: =IF(E2="CONTROL",0,1) -> 0 | G2: =IF(D2="Medellin",1,IF(D2="Cali",2,IF(D2="Baranquilla",3,0))) -> 1 | H2: 0001 | I2: =_xlfn.CONCAT(0,F2,0,G2,H2) -> 00010001
A3: 2 | B3: 1000292440 | C3: =VLOOKUP(B3,[1]BD_FINAL!$A:$H,2,FALSE) -> Yerson | D3: =VLOOKUP(B3,[1]BD_FINAL!$A:$H,3,FALSE) -> Medellin | E3: =VLOOKUP(B3,[1]BD_FINAL!$A:$H,8,FALSE) -> Control | F3: =IF(E3="CONTROL",0,1) -> 0 | G3: =IF(D3="Medellin",1,IF(D3="Cali",2,IF(D3="Baranquilla",3,0))) -> 1 | H3: 0002 | I3: =_xlfn.CONCAT(0,F3,0,G3,H3) -> 00010002
A4: 3 | B4: 1000438461 | C4: =VLOOKUP(B4,[1]BD_FINAL!$A:$H,2,FALSE) -> Juana santa | D4: =VLOOKUP(B4,[1]BD_FINAL!$A:$H,3,FALSE) -> Medellin | E4: =VLOOKUP(B4,[1]BD_FINAL!$A:$H,8,FALSE) -> Control | F4: =IF(E4="CONTROL",0,1) -> 0 | G4: =IF(D4="Medellin",1,IF(D4="Cali",2,IF(D4="Baranquilla",3,0))) -> 1 | H4: 0003 | I4: =_xlfn.CONCAT(0,F4,0,G4,H4) -> 00010003
A5: 4 | B5: 1000536137 | C5: =VLOOKUP(B5,[1]BD_FINAL!$A:$H,2,FALSE) -> Jenifer Andrea | D5: =VLOOKUP(B5,[1]BD_FINAL!$A:$H,3,FALSE) -> Medellin | E5: =VLOOKUP(B5,[1]BD_FINAL!$A:$H,8,FALSE) -> Tratamiento | F5: =IF(E5="CONTROL",0,1) -> 1 | G5: =IF(D5="Medellin",1,IF(D5="Cali",2,IF(D5="Baranquilla",3,0))) -> 1 | H5: 0004 | I5: =_xlfn.CONCAT(0,F5,0,G5,H5) -> 01010004
A6: 5 | B6: 1000538215 | C6: =VLOOKUP(B6,[1]BD_FINAL!$A:$H,2,FALSE) -> Shirley Tatiana | D6: =VLOOKUP(B6,[1]BD_FINAL!$A:$H,3,FALSE) -> Medellin | E6: =VLOOKUP(B6,[1]BD_FINAL!$A:$H,8,FALSE) -> Tratamiento | F6: =IF(E6="CONTROL",0,1) -> 1 | G6: =IF(D6="Medellin",1,IF(D6="Cali",2,IF(D6="Baranquilla",3,0))) -> 1 | H6: 0005 | I6: =_xlfn.CONCAT(0,F6,0,G6,H6) -> 01010005
A7: 6 | B7: 1000638664 | C7: =VLOOKUP(B7,[1]BD_FINAL!$A:$H,2,FALSE) -> Isabel Cristina | D7: =VLOOKUP(B7,[1]BD_FINAL!$A:$H,3,FALSE) -> Medellin | E7: =VLOOKUP(B7,[1]BD_FINAL!$A:$H,8,FALSE) -> Tratamiento | F7: =IF(E7="CONTROL",0,1) -> 1 | G7: =IF(D7="Medellin",1,IF(D7="Cali",2,IF(D7="Baranquilla",3,0))) -> 1 | H7: 0006 | I7: =_xlfn.CONCAT(0,F7,0,G7,H7) -> 01010006
A8: 7 | B8: 1000643548 | C8: =VLOOKUP(B8,[1]BD_FINAL!$A:$H,2,FALSE) -> Tatiana Inés | D8: =VLOOKUP(B8,[1]BD_FINAL!$A:$H,3,FALSE) -> Medellin | E8: =VLOOKUP(B8,[1]BD_FINAL!$A:$H,8,FALSE) -> Tratamiento | F8: =IF(E8="CONTROL",0,1) -> 1 | G8: =IF(D8="Medellin",1,IF(D8="Cali",2,IF(D8="Baranquilla",3,0))) -> 1 | H8: 0007 | I8: =_xlfn.CONCAT(0,F8,0,G8,H8) -> 01010007
A9: 8 | B9: 1000871711 | C9: =VLOOKUP(B9,[1]BD_FINAL!$A:$H,2,FALSE) -> Luz Eneida | D9: =VLOOKUP(B9,[1]BD_FINAL!$A:$H,3,FALSE) -> Medellin | E9: =VLOOKUP(B9,[1]BD_FINAL!$A:$H,8,FALSE) -> Tratamiento | F9: =IF(E9="CONTROL",0,1) -> 1 | G9: =IF(D9="Medellin",1,IF(D9="Cali",2,IF(D9="Baranquilla",3,0))) -> 1 | H9: 0008 | I9: =_xlfn.CONCAT(0,F9,0,G9,H9) -> 01010008
A10: 9 | B10: 1001033236 | C10: =VLOOKUP(B10,[1]BD_FINAL!$A:$H,2,FALSE) -> Cintia Carolina | D10: =VLOOKUP(B10,[1]BD_FINAL!$A:$H,3,FALSE) -> Medellin | E10: =VLOOKUP(B10,[1]BD_FINAL!$A:$H,8,FALSE) -> Control | F10: =IF(E10="CONTROL",0,1) -> 0 | G10: =IF(D10="Medellin",1,IF(D10="Cali",2,IF(D10="Baranquilla",3,0))) -> 1 | H10: 0009 | I10: =_xlfn.CONCAT(0,F10,0,G10,H10) -> 00010009
A11: 10 | B11: 1001139233 | C11: =VLOOKUP(B11,[1]BD_FINAL!$A:$H,2,FALSE) -> David Alexander | D11: =VLOOKUP(B11,[1]BD_FINAL!$A:$H,3,FALSE) -> Medellin | E11: =VLOOKUP(B11,[1]BD_FINAL!$A:$H,8,FALSE) -> Control | F11: =IF(E11="CONTROL",0,1) -> 0 | G11: =IF(D11="Medellin",1,IF(D11="Cali",2,IF(D11="Baranquilla",3,0))) -> 1 | H11: 0010 | I11: =_xlfn.CONCAT(0,F11,0,G11,H11) -> 00010010
A12: 11 | B12: 1001235015 | C12: =VLOOKUP(B12,[1]BD_FINAL!$A:$H,2,FALSE) -> Santiago | D12: =VLOOKUP(B12,[1]BD_FINAL!$A:$H,3,FALSE) -> Medellin | E12: =VLOOKUP(B12,[1]BD_FINAL!$A:$H,8,FALSE) -> Control | F12: =IF(E12="CONTROL",0,1) -> 0 | G12: =IF(D12="Medellin",1,IF(D12="Cali",2,IF(D12="Baranquilla",3,0))) -> 1 | H12: 0011 | I12: =_xlfn.CONCAT(0,F12,0,G12,H12) -> 00010011
A13: 12 | B13: 1001359510 | C13: =VLOOKUP(B13,[1]BD_FINAL!$A:$H,2,FALSE) -> Margarita Isabel | D13: =VLOOKUP(B13,[1]BD_FINAL!$A:$H,3,FALSE) -> Medellin | E13: =VLOOKUP(B13,[1]BD_FINAL!$A:$H,8,FALSE) -> Tratamiento | F13: =IF(E13="CONTROL",0,1) -> 1 | G13: =IF(D13="Medellin",1,IF(D13="Cali",2,IF(D13="Baranquilla",3,0))) -> 1 | H13: 0012 | I13: =_xlfn.CONCAT(0,F13,0,G13,H13) -> 01010012
... A1164: 1163 | B1164: 98657538 | C1164: =VLOOKUP(B1164,[1]BD_FINAL!$A:$H,2,FALSE) -> Jaime Alberto | D1164: =VLOOKUP(B1164,[1]BD_FINAL!$A:$H,3,FALSE) -> Medellin | E1164: =VLOOKUP(B1164,[1]BD_FINAL!$A:$H,8,FALSE) -> Control | F1164: =IF(E1164="CONTROL",0,1) -> 0 | G1164: =IF(D1164="Medellin",1,IF(D1164="Cali",2,IF(D1164="Baranquilla",3,0))) -> 1 | H1164: 1163 | I1164: =_xlfn.CONCAT(0,F1164,0,G1164,H1164) -> 00011163

Sheet INDIVIDUOS-BASELINE
A1: mem_id | B1: cod | C1: Numero de persona | D1: codigo de persona | E1: house_id | F1: mem_id
A2: 1000193972-1 | B2: 1000193972 | C2: 1 | D2: =_xlfn.CONCAT(0,C2) -> 01 | E2: =VLOOKUP(B2,'HOGARES-BASELINE'!$B:$I,8,FALSE) -> 00010001 | F2: =_xlfn.CONCAT(E2,D2) -> 0001000101
A3: 1000292440-2 | B3: 1000292440 | C3: 2 | D3: =_xlfn.CONCAT(0,C3) -> 02 | E3: =VLOOKUP(B3,'HOGARES-BASELINE'!$B:$I,8,FALSE) -> 00010002 | F3: =_xlfn.CONCAT(E3,D3) -> 0001000202
A4: 1000292440-3 | B4: 1000292440 | C4: 3 | D4: =_xlfn.CONCAT(0,C4) -> 03 | E4: =VLOOKUP(B4,'HOGARES-BASELINE'!$B:$I,8,FALSE) -> 00010002 | F4: =_xlfn.CONCAT(E4,D4) -> 0001000203
A5: 1000292440-1 | B5: 1000292440 | C5: 1 | D5: =_xlfn.CONCAT(0,C5) -> 01 | E5: =VLOOKUP(B5,'HOGARES-BASELINE'!$B:$I,8,FALSE) -> 00010002 | F5: =_xlfn.CONCAT(E5,D5) -> 0001000201
A6: 1000438461-3 | B6: 1000438461 | C6: 3 | D6: =_xlfn.CONCAT(0,C6) -> 03 | E6: =VLOOKUP(B6,'HOGARES-BASELINE'!$B:$I,8,FALSE) -> 00010003 | F6: =_xlfn.CONCAT(E6,D6) -> 0001000303
A7: 1000438461-5 | B7: 1000438461 | C7: 5 | D7: =_xlfn.CONCAT(0,C7) -> 05 | E7: =VLOOKUP(B7,'HOGARES-BASELINE'!$B:$I,8,FALSE) -> 00010003 | F7: =_xlfn.CONCAT(E7,D7) -> 0001000305
A8: 1000438461-1 | B8: 1000438461 | C8: 1 | D8: =_xlfn.CONCAT(0,C8) -> 01 | E8: =VLOOKUP(B8,'HOGARES-BASELINE'!$B:$I,8,FALSE) -> 00010003 | F8: =_xlfn.CONCAT(E8,D8) -> 0001000301
A9: 1000438461-4 | B9: 1000438461 | C9: 4 | D9: =_xlfn.CONCAT(0,C9) -> 04 | E9: =VLOOKUP(B9,'HOGARES-BASELINE'!$B:$I,8,FALSE) -> 00010003 | F9: =_xlfn.CONCAT(E9,D9) -> 0001000304
A10: 1000438461-2 | B10: 1000438461 | C10: 2 | D10: =_xlfn.CONCAT(0,C10) -> 02 | E10: =VLOOKUP(B10,'HOGARES-BASELINE'!$B:$I,8,FALSE) -> 00010003 | F10: =_xlfn.CONCAT(E10,D10) -> 0001000302
A11: 1000536137-4 | B11: 1000536137 | C11: 4 | D11: =_xlfn.CONCAT(0,C11) -> 04 | E11: =VLOOKUP(B11,'HOGARES-BASELINE'!$B:$I,8,FALSE) -> 01010004 | F11: =_xlfn.CONCAT(E11,D11) -> 0101000404
A12: 1000536137-10 | B12: 1000536137 | C12: 10 | D12: =C12 -> 10 | E12: =VLOOKUP(B12,'HOGARES-BASELINE'!$B:$I,8,FALSE) -> 01010004 | F12: =_xlfn.CONCAT(E12,D12) -> 0101000410
A13: 1000536137-12 | B13: 1000536137 | C13: 12 | D13: =C13 -> 12 | E13: =VLOOKUP(B13,'HOGARES-BASELINE'!$B:$I,8,FALSE) -> 01010004 | F13: =_xlfn.CONCAT(E13,D13) -> 0101000412
A14: 1000536137-13 | B14: 1000536137 | C14: 13 | D14: =C14 -> 13 | E14: =VLOOKUP(B14,'HOGARES-BASELINE'!$B:$I,8,FALSE) -> 01010004 | F14: =_xlfn.CONCAT(E14,D14) -> 0101000413
A15: 1000536137-5 | B15: 1000536137 | C15: 5 | D15: =_xlfn.CONCAT(0,C15) -> 05 | E15: =VLOOKUP(B15,'HOGARES-BASELINE'!$B:$I,8,FALSE) -> 01010004 | F15: =_xlfn.CONCAT(E15,D15) -> 0101000405
A16: 1000536137-8 | B16: 1000536137 | C16: 8 | D16: =_xlfn.CONCAT(0,C16) -> 08 | E16: =VLOOKUP(B16,'HOGARES-BASELINE'!$B:$I,8,FALSE) -> 01010004 | F16: =_xlfn.CONCAT(E16,D16) -> 0101000408
A17: 1000536137-7 | B17: 1000536137 | C17: 7 | D17: =_xlfn.CONCAT(0,C17) -> 07 | E17: =VLOOKUP(B17,'HOGARES-BASELINE'!$B:$I,8,FALSE) -> 01010004 | F17: =_xlfn.CONCAT(E17,D17) -> 0101000407
A18: 1000536137-1 | B18: 1000536137 | C18: 1 | D18: =_xlfn.CONCAT(0,C18) -> 01 | E18: =VLOOKUP(B18,'HOGARES-BASELINE'!$B:$I,8,FALSE) -> 01010004 | F18: =_xlfn.CONCAT(E18,D18) -> 0101000401
A19: 1000536137-2 | B19: 1000536137 | C19: 2 | D19: =_xlfn.CONCAT(0,C19) -> 02 | E19: =VLOOKUP(B19,'HOGARES-BASELINE'!$B:$I,8,FALSE) -> 01010004 | F19: =_xlfn.CONCAT(E19,D19) -> 0101000402
A20: 1000536137-3 | B20: 1000536137 | C20: 3 | D20: =_xlfn.CONCAT(0,C20) -> 03 | E20: =VLOOKUP(B20,'HOGARES-BASELINE'!$B:$I,8,FALSE) -> 01010004 | F20: =_xlfn.CONCAT(E20,D20) -> 0101000403
A21: 1000536137-6 | B21: 1000536137 | C21: 6 | D21: =_xlfn.CONCAT(0,C21) -> 06 | E21: =VLOOKUP(B21,'HOGARES-BASELINE'!$B:$I,8,FALSE) -> 01010004 | F21: =_xlfn.CONCAT(E21,D21) -> 0101000406
A22: 1000536137-11 | B22: 1000536137 | C22: 11 | D22: =C22 -> 11 | E22: =VLOOKUP(B22,'HOGARES-BASELINE'!$B:$I,8,FALSE) -> 01010004 | F22: =_xlfn.CONCAT(E22,D22) -> 0101000411
A23: 1000536137-9 | B23: 1000536137 | C23: 9 | D23: =_xlfn.CONCAT(0,C23) -> 09 | E23: =VLOOKUP(B23,'HOGARES-BASELINE'!$B:$I,8,FALSE) -> 01010004 | F23: =_xlfn.CONCAT(E23,D23) -> 0101000409
A24: 1000538215-3 | B24: 1000538215 | C24: 3 | D24: =_xlfn.CONCAT(0,C24) -> 03 | E24: =VLOOKUP(B24,'HOGARES-BASELINE'!$B:$I,8,FALSE) -> 01010005 | F24: =_xlfn.CONCAT(E24,D24) -> 0101000503
A25: 1000538215-2 | B25: 1000538215 | C25: 2 | D25: =_xlfn.CONCAT(0,C25) -> 02 | E25: =VLOOKUP(B25,'HOGARES-BASELINE'!$B:$I,8,FALSE) -> 01010005 | F25: =_xlfn.CONCAT(E25,D25) -> 0101000502
A26: 1000538215-4 | B26: 1000538215 | C26: 4 | D26: =_xlfn.CONCAT(0,C26) -> 04 | E26: =VLOOKUP(B26,'HOGARES-BASELINE'!$B:$I,8,FALSE) -> 01010005 | F26: =_xlfn.CONCAT(E26,D26) -> 0101000504
A27: 1000538215-1 | B27: 1000538215 | C27: 1 | D27: =_xlfn.CONCAT(0,C27) -> 01 | E27: =VLOOKUP(B27,'HOGARES-BASELINE'!$B:$I,8,FALSE) -> 01010005 | F27: =_xlfn.CONCAT(E27,D27) -> 0101000501
A28: 1000638664-1 | B28: 1000638664 | C28: 1 | D28: =_xlfn.CONCAT(0,C28) -> 01 | E28: =VLOOKUP(B28,'HOGARES-BASELINE'!$B:$I,8,FALSE) -> 01010006 | F28: =_xlfn.CONCAT(E28,D28) -> 0101000601
A29: 1000638664-2 | B29: 1000638664 | C29: 2 | D29: =_xlfn.CONCAT(0,C29) -> 02 | E29: =VLOOKUP(B29,'HOGARES-BASELINE'!$B:$I,8,FALSE) -> 01010006 | F29: =_xlfn.CONCAT(E29,D29) -> 0101000602
A30: 1000638664-3 | B30: 1000638664 | C30: 3 | D30: =_xlfn.CONCAT(0,C30) -> 03 | E30: =VLOOKUP(B30,'HOGARES-BASELINE'!$B:$I,8,FALSE) -> 01010006 | F30: =_xlfn.CONCAT(E30,D30) -> 0101000603
A31: 1000643548-2 | B31: 1000643548 | C31: 2 | D31: =_xlfn.CONCAT(0,C31) -> 02 | E31: =VLOOKUP(B31,'HOGARES-BASELINE'!$B:$I,8,FALSE) -> 01010007 | F31: =_xlfn.CONCAT(E31,D31) -> 0101000702
A32: 1000643548-1 | B32: 1000643548 | C32: 1 | D32: =_xlfn.CONCAT(0,C32) -> 01 | E32: =VLOOKUP(B32,'HOGARES-BASELINE'!$B:$I,8,FALSE) -> 01010007 | F32: =_xlfn.CONCAT(E32,D32) -> 0101000701
A33: 1000871711-2 | B33: 1000871711 | C33: 2 | D33: =_xlfn.CONCAT(0,C33) -> 02 | E33: =VLOOKUP(B33,'HOGARES-BASELINE'!$B:$I,8,FALSE) -> 01010008 | F33: =_xlfn.CONCAT(E33,D33) -> 0101000802
A34: 1000871711-1 | B34: 1000871711 | C34: 1 | D34: =_xlfn.CONCAT(0,C34) -> 01 | E34: =VLOOKUP(B34,'HOGARES-BASELINE'!$B:$I,8,FALSE) -> 01010008 | F34: =_xlfn.CONCAT(E34,D34) -> 0101000801
... A176: 1017247299-8 | B176: 1017247299 | C176: 8 | D176: =_xlfn.CONCAT(0,C176) -> 08 | E176: =VLOOKUP(B176,'HOGARES-BASELINE'!$B:$I,8,FALSE) -> 01010047 | F176: =_xlfn.CONCAT(E176,D176) -> 0101004708
A177: 1017247299-10 | B177: 1017247299 | C177: 10 | D177: =C177 -> 10 | E177: =VLOOKUP(B177,'HOGARES-BASELINE'!$B:$I,8,FALSE) -> 01010047 | F177: =_xlfn.CONCAT(E177,D177) -> 0101004710
A178: 1017247299-3 | B178: 1017247299 | C178: 3 | D178: =_xlfn.CONCAT(0,C178) -> 03 | E178: =VLOOKUP(B178,'HOGARES-BASELINE'!$B:$I,8,FALSE) -> 01010047 | F178: =_xlfn.CONCAT(E178,D178) -> 0101004703
A179: 1017247299-4 | B179: 1017247299 | C179: 4 | D179: =_xlfn.CONCAT(0,C179) -> 04 | E179: =VLOOKUP(B179,'HOGARES-BASELINE'!$B:$I,8,FALSE) -> 01010047 | F179: =_xlfn.CONCAT(E179,D179) -> 0101004704
A180: 1017247299-7 | B180: 1017247299 | C180: 7 | D180: =_xlfn.CONCAT(0,C180) -> 07 | E180: =VLOOKUP(B180,'HOGARES-BASELINE'!$B:$I,8,FALSE) -> 01010047 | F180: =_xlfn.CONCAT(E180,D180) -> 0101004707
A181: 1017248051-4 | B181: 1017248051 | C181: 4 | D181: =_xlfn.CONCAT(0,C181) -> 04 | E181: =VLOOKUP(B181,'HOGARES-BASELINE'!$B:$I,8,FALSE) -> 01010048 | F181: =_xlfn.CONCAT(E181,D181) -> 0101004804
...

Sheet HOGARES-ENDLINE
A1: start_p10 | B1: house_id
A2: 670254 | B2: =VLOOKUP(A2,'HOGARES-BASELINE'!$B:$I,8,FALSE) -> 01011005
A3: 761321 | B3: =VLOOKUP(A3,'HOGARES-BASELINE'!$B:$I,8,FALSE) -> 01011096
A4: 832608 | B4: =VLOOKUP(A4,'HOGARES-BASELINE'!$B:$I,8,FALSE) -> 01031108
A5: 1381356 | B5: =VLOOKUP(A5,'HOGARES-BASELINE'!$B:$I,8,FALSE) -> 01020260
A6: 1522015 | B6: =VLOOKUP(A6,'HOGARES-BASELINE'!$B:$I,8,FALSE) -> 00020270
A7: 1586059 | B7: =VLOOKUP(A7,'HOGARES-BASELINE'!$B:$I,8,FALSE) -> 01020272
A8: 1747298 | B8: =VLOOKUP(A8,'HOGARES-BASELINE'!$B:$I,8,FALSE) -> 00030303
A9: 2272778 | B9: =VLOOKUP(A9,'HOGARES-BASELINE'!$B:$I,8,FALSE) -> 00020430
A10: 2680456 | B10: =VLOOKUP(A10,'HOGARES-BASELINE'!$B:$I,8,FALSE) -> 00020472
A11: 2699661 | B11: =VLOOKUP(A11,'HOGARES-BASELINE'!$B:$I,8,FALSE) -> 01020473
A12: 2775711 | B12: =VLOOKUP(A12,'HOGARES-BASELINE'!$B:$I,8,FALSE) -> 00010476
A13: 3430889 | B13: =VLOOKUP(A13,'HOGARES-BASELINE'!$B:$I,8,FALSE) -> 00010733
... A1095: 1214737888 | B1095: =VLOOKUP(A1095,'HOGARES-BASELINE'!$B:$I,8,FALSE) -> 00010251

Sheet INDIVIDUOS-ENDLINE
A1: mem_id | B1: cod | C1: Numero de persona | D1: codigo de persona | E1: house_id | F1: mem_id
A2: 670254-1 | B2: 670254 | C2: 1 | D2: =_xlfn.CONCAT(0,C2) -> 01 | E2: =VLOOKUP(B2,'HOGARES-ENDLINE'!$A:$B,2,FALSE) -> 01011005 | F2: =_xlfn.CONCAT(E2,D2) -> 0101100501
A3: 670254-2 | B3: 670254 | C3: 2 | D3: =_xlfn.CONCAT(0,C3) -> 02 | E3: =VLOOKUP(B3,'HOGARES-ENDLINE'!$A:$B,2,FALSE) -> 01011005 | F3: =_xlfn.CONCAT(E3,D3) -> 0101100502
A4: 670254-3 | B4: 670254 | C4: 3 | D4: =_xlfn.CONCAT(0,C4) -> 03 | E4: =VLOOKUP(B4,'HOGARES-ENDLINE'!$A:$B,2,FALSE) -> 01011005 | F4: =_xlfn.CONCAT(E4,D4) -> 0101100503
A5: 670254-4 | B5: 670254 | C5: 4 | D5: =_xlfn.CONCAT(0,C5) -> 04 | E5: =VLOOKUP(B5,'HOGARES-ENDLINE'!$A:$B,2,FALSE) -> 01011005 | F5: =_xlfn.CONCAT(E5,D5) -> 0101100504
A6: 761321-1 | B6: 761321 | C6: 1 | D6: =_xlfn.CONCAT(0,C6) -> 01 | E6: =VLOOKUP(B6,'HOGARES-ENDLINE'!$A:$B,2,FALSE) -> 01011096 | F6: =_xlfn.CONCAT(E6,D6) -> 0101109601
A7: 832608-3 | B7: 832608 | C7: 3 | D7: =_xlfn.CONCAT(0,C7) -> 03 | E7: =VLOOKUP(B7,'HOGARES-ENDLINE'!$A:$B,2,FALSE) -> 01031108 | F7: =_xlfn.CONCAT(E7,D7) -> 0103110803
A8: 832608-1 | B8: 832608 | C8: 1 | D8: =_xlfn.CONCAT(0,C8) -> 01 | E8: =VLOOKUP(B8,'HOGARES-ENDLINE'!$A:$B,2,FALSE) -> 01031108 | F8: =_xlfn.CONCAT(E8,D8) -> 0103110801
A9: 832608-4 | B9: 832608 | C9: 4 | D9: =_xlfn.CONCAT(0,C9) -> 04 | E9: =VLOOKUP(B9,'HOGARES-ENDLINE'!$A:$B,2,FALSE) -> 01031108 | F9: =_xlfn.CONCAT(E9,D9) -> 0103110804
A10: 832608-2 | B10: 832608 | C10: 2 | D10: =_xlfn.CONCAT(0,C10) -> 02 | E10: =VLOOKUP(B10,'HOGARES-ENDLINE'!$A:$B,2,FALSE) -> 01031108 | F10: =_xlfn.CONCAT(E10,D10) -> 0103110802
A11: 1381356-1 | B11: 1381356 | C11: 1 | D11: =_xlfn.CONCAT(0,C11) -> 01 | E11: =VLOOKUP(B11,'HOGARES-ENDLINE'!$A:$B,2,FALSE) -> 01020260 | F11: =_xlfn.CONCAT(E11,D11) -> 0102026001
A12: 1522015-1 | B12: 1522015 | C12: 1 | D12: =_xlfn.CONCAT(0,C12) -> 01 | E12: =VLOOKUP(B12,'HOGARES-ENDLINE'!$A:$B,2,FALSE) -> 00020270 | F12: =_xlfn.CONCAT(E12,D12) -> 0002027001
A13: 1586059-1 | B13: 1586059 | C13: 1 | D13: =_xlfn.CONCAT(0,C13) -> 01 | E13: =VLOOKUP(B13,'HOGARES-ENDLINE'!$A:$B,2,FALSE) -> 01020272 | F13: =_xlfn.CONCAT(E13,D13) -> 0102027201
... A46: 6307220-1 | B46: 6307220 | C46: 1 | D46: =_xlfn.CONCAT(0,C46) -> 01 | E46: =VLOOKUP(B46,'HOGARES-ENDLINE'!$A:$B,2,FALSE) -> 01020957 | F46: =_xlfn.CONCAT(E46,D46) -> 0102095701
A47: 7411480-11 | B47: 7411480 | C47: 11 | D47: =C47 -> 11 | E47: =VLOOKUP(B47,'HOGARES-ENDLINE'!$A:$B,2,FALSE) -> 00031081 | F47: =_xlfn.CONCAT(E47,D47) -> 0003108111
A48: 7411480-4 | B48: 7411480 | C48: 4 | D48: =_xlfn.CONCAT(0,C48) -> 04 | E48: =VLOOKUP(B48,'HOGARES-ENDLINE'!$A:$B,2,FALSE) -> 00031081 | F48: =_xlfn.CONCAT(E48,D48) -> 0003108104
A49: 7411480-3 | B49: 7411480 | C49: 3 | D49: =_xlfn.CONCAT(0,C49) -> 03 | E49: =VLOOKUP(B49,'HOGARES-ENDLINE'!$A:$B,2,FALSE) -> 00031081 | F49: =_xlfn.CONCAT(E49,D49) -> 0003108103
A50: 7411480-8 | B50: 7411480 | C50: 8 | D50: =_xlfn.CONCAT(0,C50) -> 08 | E50: =VLOOKUP(B50,'HOGARES-ENDLINE'!$A:$B,2,FALSE) -> 00031081 | F50: =_xlfn.CONCAT(E50,D50) -> 0003108108
A51: 7411480-13 | B51: 7411480 | C51: 13 | D51: =C51 -> 13 | E51: =VLOOKUP(B51,'HOGARES-ENDLINE'!$A:$B,2,FALSE) -> 00031081 | F51: =_xlfn.CONCAT(E51,D51) -> 0003108113
A52: 7411480-10 | B52: 7411480 | C52: 10 | D52: =C52 -> 10 | E52: =VLOOKUP(B52,'HOGARES-ENDLINE'!$A:$B,2,FALSE) -> 00031081 | F52: =_xlfn.CONCAT(E52,D52) -> 0003108110
A53: 7411480-6 | B53: 7411480 | C53: 6 | D53: =_xlfn.CONCAT(0,C53) -> 06 | E53: =VLOOKUP(B53,'HOGARES-ENDLINE'!$A:$B,2,FALSE) -> 00031081 | F53: =_xlfn.CONCAT(E53,D53) -> 0003108106
A54: 7411480-12 | B54: 7411480 | C54: 12 | D54: =C54 -> 12 | E54: =VLOOKUP(B54,'HOGARES-ENDLINE'!$A:$B,2,FALSE) -> 00031081 | F54: =_xlfn.CONCAT(E54,D54) -> 0003108112
A55: 7411480-9 | B55: 7411480 | C55: 9 | D55: =_xlfn.CONCAT(0,C55) -> 09 | E55: =VLOOKUP(B55,'HOGARES-ENDLINE'!$A:$B,2,FALSE) -> 00031081 | F55: =_xlfn.CONCAT(E55,D55) -> 0003108109
A56: 7411480-7 | B56: 7411480 | C56: 7 | D56: =_xlfn.CONCAT(0,C56) -> 07 | E56: =VLOOKUP(B56,'HOGARES-ENDLINE'!$A:$B,2,FALSE) -> 00031081 | F56: =_xlfn.CONCAT(E56,D56) -> 0003108107
A57: 7411480-2 | B57: 7411480 | C57: 2 | D57: =_xlfn.CONCAT(0,C57) -> 02 | E57: =VLOOKUP(B57,'HOGARES-ENDLINE'!$A:$B,2,FALSE) -> 00031081 | F57: =_xlfn.CONCAT(E57,D57) -> 0003108102
A58: 7411480-1 | B58: 7411480 | C58: 1 | D58: =_xlfn.CONCAT(0,C58) -> 01 | E58: =VLOOKUP(B58,'HOGARES-ENDLINE'!$A:$B,2,FALSE) -> 00031081 | F58: =_xlfn.CONCAT(E58,D58) -> 0003108101
A59: 7411480-5 | B59: 7411480 | C59: 5 | D59: =_xlfn.CONCAT(0,C59) -> 05 | E59: =VLOOKUP(B59,'HOGARES-ENDLINE'!$A:$B,2,FALSE) -> 00031081 | F59: =_xlfn.CONCAT(E59,D59) -> 0003108105
A60: 7420358-1 | B60: 7420358 | C60: 1 | D60: =_xlfn.CONCAT(0,C60) -> 01 | E60: =VLOOKUP(B60,'HOGARES-ENDLINE'!$A:$B,2,FALSE) -> 00031082 | F60: =_xlfn.CONCAT(E60,D60) -> 0003108201
A61: 7420358-2 | B61: 7420358 | C61: 2 | D61: =_xlfn.CONCAT(0,C61) -> 02 | E61: =VLOOKUP(B61,'HOGARES-ENDLINE'!$A:$B,2,FALSE) -> 00031082 | F61: =_xlfn.CONCAT(E61,D61) -> 0003108202
A62: 7435553-6 | B62: 7435553 | C62: 6 | D62: =_xlfn.CONCAT(0,C62) -> 06 | E62: =VLOOKUP(B62,'HOGARES-ENDLINE'!$A:$B,2,FALSE) -> 00031083 | F62: =_xlfn.CONCAT(E62,D62) -> 0003108306
A63: 7435553-5 | B63: 7435553 | C63: 5 | D63: =_xlfn.CONCAT(0,C63) -> 05 | E63: =VLOOKUP(B63,'HOGARES-ENDLINE'!$A:$B,2,FALSE) -> 00031083 | F63: =_xlfn.CONCAT(E63,D63) -> 0003108305
A64: 7435553-3 | B64: 7435553 | C64: 3 | D64: =_xlfn.CONCAT(0,C64) -> 03 | E64: =VLOOKUP(B64,'HOGARES-ENDLINE'!$A:$B,2,FALSE) -> 00031083 | F64: =_xlfn.CONCAT(E64,D64) -> 0003108303
A65: 7435553-1 | B65: 7435553 | C65: 1 | D65: =_xlfn.CONCAT(0,C65) -> 01 | E65: =VLOOKUP(B65,'HOGARES-ENDLINE'!$A:$B,2,FALSE) -> 00031083 | F65: =_xlfn.CONCAT(E65,D65) -> 0003108301
A66: 7435553-2 | B66: 7435553 | C66: 2 | D66: =_xlfn.CONCAT(0,C66) -> 02 | E66: =VLOOKUP(B66,'HOGARES-ENDLINE'!$A:$B,2,FALSE) -> 00031083 | F66: =_xlfn.CONCAT(E66,D66) -> 0003108302
... A1172: 32678914-3 | B1172: 32678914 | C1172: 3 | D1172: =_xlfn.CONCAT(0,C1172) -> 03 | E1172: =VLOOKUP(B1172,'HOGARES-ENDLINE'!$A:$B,2,FALSE) -> 00030641 | F1172: =_xlfn.CONCAT(E1172,D1172) -> 0003064103
A1173: 32678914-10 | B1173: 32678914 | C1173: 10 | D1173: =C1173 -> 10 | E1173: =VLOOKUP(B1173,'HOGARES-ENDLINE'!$A:$B,2,FALSE) -> 00030641 | F1173: =_xlfn.CONCAT(E1173,D1173) -> 0003064110
A1174: 32678914-7 | B1174: 32678914 | C1174: 7 | D1174: =_xlfn.CONCAT(0,C1174) -> 07 | E1174: =VLOOKUP(B1174,'HOGARES-ENDLINE'!$A:$B,2,FALSE) -> 00030641 | F1174: =_xlfn.CONCAT(E1174,D1174) -> 0003064107
A1175: 32678914-8 | B1175: 32678914 | C1175: 8 | D1175: =_xlfn.CONCAT(0,C1175) -> 08 | E1175: =VLOOKUP(B1175,'HOGARES-ENDLINE'!$A:$B,2,FALSE) -> 00030641 | F1175: =_xlfn.CONCAT(E1175,D1175) -> 0003064108
A1176: 32678914-6 | B1176: 32678914 | C1176: 6 | D1176: =_xlfn.CONCAT(0,C1176) -> 06 | E1176: =VLOOKUP(B1176,'HOGARES-ENDLINE'!$A:$B,2,FALSE) -> 00030641 | F1176: =_xlfn.CONCAT(E1176,D1176) -> 0003064106
A1177: 32678914-4 | B1177: 32678914 | C1177: 4 | D1177: =_xlfn.CONCAT(0,C1177) -> 04 | E1177: =VLOOKUP(B1177,'HOGARES-ENDLINE'!$A:$B,2,FALSE) -> 00030641 | F1177: =_xlfn.CONCAT(E1177,D1177) -> 0003064104
...
